[Sun Oct 19 07:35:03 2014] [notice] Apache/2.2.22 (Debian) mod_wsgi/3.3 Python/2.7.3 configured -- resuming normal operations
[Sun Oct 19 08:54:35 2014] [error] [client 95.183.244.29] Invalid method in request                 
[Sun Oct 19 14:06:11 2014] [error] [client 108.183.50.177] client sent HTTP/1.1 request without hostname (see RFC2616 section 14.23): /tmUnblock.cgi
[Sun Oct 19 14:48:08 2014] [error] [client 211.24.41.119] client sent HTTP/1.1 request without hostname (see RFC2616 section 14.23): /tmUnblock.cgi
[Sun Oct 19 19:20:07 2014] [error] [client 112.134.195.249] File does not exist: /var/www/favicon.ico
[Sun Oct 19 19:34:44 2014] [error] [client 94.102.49.82] File does not exist: /var/www/admin
[Sun Oct 19 20:21:21 2014] [notice] caught SIGTERM, shutting down
[Sun Oct 19 20:21:22 2014] [notice] Apache/2.2.22 (Debian) mod_wsgi/3.3 Python/2.7.3 configured -- resuming normal operations
[Sun Oct 19 20:21:28 2014] [crit] [client 112.134.195.249] configuration error:  couldn't perform authentication. AuthType not set!: /
[Sun Oct 19 20:21:47 2014] [crit] [client 112.134.195.249] configuration error:  couldn't perform authentication. AuthType not set!: /ato.care
[Sun Oct 19 20:21:50 2014] [crit] [client 112.134.195.249] configuration error:  couldn't perform authentication. AuthType not set!: /ato.care
[Sun Oct 19 20:21:59 2014] [crit] [client 112.134.195.249] configuration error:  couldn't perform authentication. AuthType not set!: /ato.care/care
[Sun Oct 19 20:22:07 2014] [crit] [client 112.134.195.249] configuration error:  couldn't perform authentication. AuthType not set!: /
[Sun Oct 19 20:29:21 2014] [notice] caught SIGTERM, shutting down
[Sun Oct 19 20:29:22 2014] [notice] Apache/2.2.22 (Debian) mod_wsgi/3.3 Python/2.7.3 configured -- resuming normal operations
[Sun Oct 19 20:29:29 2014] [crit] [client 112.134.195.249] configuration error:  couldn't perform authentication. AuthType not set!: /
[Sun Oct 19 20:29:35 2014] [crit] [client 112.134.195.249] configuration error:  couldn't perform authentication. AuthType not set!: /ato.care
[Sun Oct 19 20:29:43 2014] [crit] [client 112.134.195.249] configuration error:  couldn't perform authentication. AuthType not set!: /atosite
[Sun Oct 19 23:31:47 2014] [crit] [client 66.249.81.55] configuration error:  couldn't perform authentication. AuthType not set!: /
[Mon Oct 20 06:41:43 2014] [crit] [client 66.249.81.55] configuration error:  couldn't perform authentication. AuthType not set!: /api/questionary/6/
[Mon Oct 20 06:41:43 2014] [crit] [client 66.249.93.55] configuration error:  couldn't perform authentication. AuthType not set!: /api/questionary/6/, referer: http://www.google.com/search
[Mon Oct 20 07:45:30 2014] [crit] [client 36.226.117.54] configuration error:  couldn't perform authentication. AuthType not set!: /
[Mon Oct 20 07:51:35 2014] [crit] [client 66.249.81.55] configuration error:  couldn't perform authentication. AuthType not set!: /api/questionary/5/
[Mon Oct 20 07:51:35 2014] [crit] [client 66.249.93.55] configuration error:  couldn't perform authentication. AuthType not set!: /api/questionary/5/, referer: http://www.google.com/search
[Mon Oct 20 08:52:49 2014] [error] [client 68.9.109.33] client sent HTTP/1.1 request without hostname (see RFC2616 section 14.23): /tmUnblock.cgi
[Mon Oct 20 09:36:13 2014] [crit] [client 65.207.23.201] configuration error:  couldn't perform authentication. AuthType not set!: /user/soapCaller.bs
[Mon Oct 20 11:51:48 2014] [crit] [client 120.151.247.83] configuration error:  couldn't perform authentication. AuthType not set!: /
[Mon Oct 20 12:57:06 2014] [crit] [client 198.20.69.74] configuration error:  couldn't perform authentication. AuthType not set!: /
[Mon Oct 20 15:32:21 2014] [notice] caught SIGTERM, shutting down
[Mon Oct 20 15:32:22 2014] [notice] Apache/2.2.22 (Debian) mod_wsgi/3.3 Python/2.7.3 configured -- resuming normal operations
[Mon Oct 20 15:32:43 2014] [crit] [client 112.134.180.165] configuration error:  couldn't perform authentication. AuthType not set!: /
[Mon Oct 20 15:32:57 2014] [crit] [client 112.134.180.165] configuration error:  couldn't perform authentication. AuthType not set!: /care
[Mon Oct 20 15:38:06 2014] [notice] caught SIGTERM, shutting down
[Mon Oct 20 15:38:07 2014] [notice] Apache/2.2.22 (Debian) mod_wsgi/3.3 Python/2.7.3 configured -- resuming normal operations
[Mon Oct 20 15:39:02 2014] [crit] [client 112.134.180.165] configuration error:  couldn't perform authentication. AuthType not set!: /care
[Mon Oct 20 15:39:30 2014] [notice] caught SIGTERM, shutting down
[Mon Oct 20 15:39:31 2014] [notice] Apache/2.2.22 (Debian) mod_wsgi/3.3 Python/2.7.3 configured -- resuming normal operations
[Mon Oct 20 15:39:34 2014] [error] [client 112.134.180.165] mod_wsgi (pid=2191): Target WSGI script '/var/www/atosite/atosite/wsgi.py' cannot be loaded as Python module.
[Mon Oct 20 15:39:34 2014] [error] [client 112.134.180.165] mod_wsgi (pid=2191): Exception occurred processing WSGI script '/var/www/atosite/atosite/wsgi.py'.
[Mon Oct 20 15:39:34 2014] [error] [client 112.134.180.165] Traceback (most recent call last):
[Mon Oct 20 15:39:34 2014] [error] [client 112.134.180.165]   File "/var/www/atosite/atosite/wsgi.py", line 14, in <module>
[Mon Oct 20 15:39:34 2014] [error] [client 112.134.180.165]     application = get_wsgi_application()
[Mon Oct 20 15:39:34 2014] [error] [client 112.134.180.165]   File "/usr/local/lib/python2.7/dist-packages/django/core/wsgi.py", line 14, in get_wsgi_application
[Mon Oct 20 15:39:34 2014] [error] [client 112.134.180.165]     django.setup()
[Mon Oct 20 15:39:34 2014] [error] [client 112.134.180.165]   File "/usr/local/lib/python2.7/dist-packages/django/__init__.py", line 21, in setup
[Mon Oct 20 15:39:34 2014] [error] [client 112.134.180.165]     apps.populate(settings.INSTALLED_APPS)
[Mon Oct 20 15:39:34 2014] [error] [client 112.134.180.165]   File "/usr/local/lib/python2.7/dist-packages/django/apps/registry.py", line 85, in populate
[Mon Oct 20 15:39:34 2014] [error] [client 112.134.180.165]     app_config = AppConfig.create(entry)
[Mon Oct 20 15:39:34 2014] [error] [client 112.134.180.165]   File "/usr/local/lib/python2.7/dist-packages/django/apps/config.py", line 87, in create
[Mon Oct 20 15:39:34 2014] [error] [client 112.134.180.165]     module = import_module(entry)
[Mon Oct 20 15:39:34 2014] [error] [client 112.134.180.165]   File "/usr/lib/python2.7/importlib/__init__.py", line 37, in import_module
[Mon Oct 20 15:39:34 2014] [error] [client 112.134.180.165]     __import__(name)
[Mon Oct 20 15:39:34 2014] [error] [client 112.134.180.165] ImportError: No module named registration
[Mon Oct 20 15:39:37 2014] [error] [client 112.134.180.165] mod_wsgi (pid=2191): Target WSGI script '/var/www/atosite/atosite/wsgi.py' cannot be loaded as Python module.
[Mon Oct 20 15:39:37 2014] [error] [client 112.134.180.165] mod_wsgi (pid=2191): Exception occurred processing WSGI script '/var/www/atosite/atosite/wsgi.py'.
[Mon Oct 20 15:39:37 2014] [error] [client 112.134.180.165] Traceback (most recent call last):
[Mon Oct 20 15:39:37 2014] [error] [client 112.134.180.165]   File "/var/www/atosite/atosite/wsgi.py", line 14, in <module>
[Mon Oct 20 15:39:37 2014] [error] [client 112.134.180.165]     application = get_wsgi_application()
[Mon Oct 20 15:39:37 2014] [error] [client 112.134.180.165]   File "/usr/local/lib/python2.7/dist-packages/django/core/wsgi.py", line 14, in get_wsgi_application
[Mon Oct 20 15:39:37 2014] [error] [client 112.134.180.165]     django.setup()
[Mon Oct 20 15:39:37 2014] [error] [client 112.134.180.165]   File "/usr/local/lib/python2.7/dist-packages/django/__init__.py", line 21, in setup
[Mon Oct 20 15:39:37 2014] [error] [client 112.134.180.165]     apps.populate(settings.INSTALLED_APPS)
[Mon Oct 20 15:39:37 2014] [error] [client 112.134.180.165]   File "/usr/local/lib/python2.7/dist-packages/django/apps/registry.py", line 78, in populate
[Mon Oct 20 15:39:37 2014] [error] [client 112.134.180.165]     raise RuntimeError("populate() isn't reentrant")
[Mon Oct 20 15:39:37 2014] [error] [client 112.134.180.165] RuntimeError: populate() isn't reentrant
[Mon Oct 20 15:39:37 2014] [error] [client 112.134.180.165] mod_wsgi (pid=2192): Target WSGI script '/var/www/atosite/atosite/wsgi.py' cannot be loaded as Python module.
[Mon Oct 20 15:39:37 2014] [error] [client 112.134.180.165] mod_wsgi (pid=2192): Exception occurred processing WSGI script '/var/www/atosite/atosite/wsgi.py'.
[Mon Oct 20 15:39:37 2014] [error] [client 112.134.180.165] Traceback (most recent call last):
[Mon Oct 20 15:39:37 2014] [error] [client 112.134.180.165]   File "/var/www/atosite/atosite/wsgi.py", line 14, in <module>
[Mon Oct 20 15:39:37 2014] [error] [client 112.134.180.165]     application = get_wsgi_application()
[Mon Oct 20 15:39:37 2014] [error] [client 112.134.180.165]   File "/usr/local/lib/python2.7/dist-packages/django/core/wsgi.py", line 14, in get_wsgi_application
[Mon Oct 20 15:39:37 2014] [error] [client 112.134.180.165]     django.setup()
[Mon Oct 20 15:39:37 2014] [error] [client 112.134.180.165]   File "/usr/local/lib/python2.7/dist-packages/django/__init__.py", line 21, in setup
[Mon Oct 20 15:39:37 2014] [error] [client 112.134.180.165]     apps.populate(settings.INSTALLED_APPS)
[Mon Oct 20 15:39:37 2014] [error] [client 112.134.180.165]   File "/usr/local/lib/python2.7/dist-packages/django/apps/registry.py", line 85, in populate
[Mon Oct 20 15:39:37 2014] [error] [client 112.134.180.165]     app_config = AppConfig.create(entry)
[Mon Oct 20 15:39:37 2014] [error] [client 112.134.180.165]   File "/usr/local/lib/python2.7/dist-packages/django/apps/config.py", line 87, in create
[Mon Oct 20 15:39:37 2014] [error] [client 112.134.180.165]     module = import_module(entry)
[Mon Oct 20 15:39:37 2014] [error] [client 112.134.180.165]   File "/usr/lib/python2.7/importlib/__init__.py", line 37, in import_module
[Mon Oct 20 15:39:37 2014] [error] [client 112.134.180.165]     __import__(name)
[Mon Oct 20 15:39:37 2014] [error] [client 112.134.180.165] ImportError: No module named registration
[Mon Oct 20 16:08:24 2014] [notice] caught SIGTERM, shutting down
[Mon Oct 20 16:08:25 2014] [notice] Apache/2.2.22 (Debian) mod_wsgi/3.3 Python/2.7.3 configured -- resuming normal operations
[Mon Oct 20 16:08:32 2014] [error] [client 112.134.180.165] mod_wsgi (pid=8024): Target WSGI script '/var/www/atosite/atosite/wsgi.py' cannot be loaded as Python module.
[Mon Oct 20 16:08:32 2014] [error] [client 112.134.180.165] mod_wsgi (pid=8024): Exception occurred processing WSGI script '/var/www/atosite/atosite/wsgi.py'.
[Mon Oct 20 16:08:32 2014] [error] [client 112.134.180.165] Traceback (most recent call last):
[Mon Oct 20 16:08:32 2014] [error] [client 112.134.180.165]   File "/var/www/atosite/atosite/wsgi.py", line 14, in <module>
[Mon Oct 20 16:08:32 2014] [error] [client 112.134.180.165]     application = get_wsgi_application()
[Mon Oct 20 16:08:32 2014] [error] [client 112.134.180.165]   File "/usr/local/lib/python2.7/dist-packages/django/core/wsgi.py", line 14, in get_wsgi_application
[Mon Oct 20 16:08:32 2014] [error] [client 112.134.180.165]     django.setup()
[Mon Oct 20 16:08:32 2014] [error] [client 112.134.180.165]   File "/usr/local/lib/python2.7/dist-packages/django/__init__.py", line 21, in setup
[Mon Oct 20 16:08:32 2014] [error] [client 112.134.180.165]     apps.populate(settings.INSTALLED_APPS)
[Mon Oct 20 16:08:32 2014] [error] [client 112.134.180.165]   File "/usr/local/lib/python2.7/dist-packages/django/apps/registry.py", line 108, in populate
[Mon Oct 20 16:08:32 2014] [error] [client 112.134.180.165]     app_config.import_models(all_models)
[Mon Oct 20 16:08:32 2014] [error] [client 112.134.180.165]   File "/usr/local/lib/python2.7/dist-packages/django/apps/config.py", line 197, in import_models
[Mon Oct 20 16:08:32 2014] [error] [client 112.134.180.165]     self.models_module = import_module(models_module_name)
[Mon Oct 20 16:08:32 2014] [error] [client 112.134.180.165]   File "/usr/lib/python2.7/importlib/__init__.py", line 37, in import_module
[Mon Oct 20 16:08:32 2014] [error] [client 112.134.180.165]     __import__(name)
[Mon Oct 20 16:08:32 2014] [error] [client 112.134.180.165]   File "/usr/local/lib/python2.7/dist-packages/django/contrib/auth/models.py", line 40, in <module>
[Mon Oct 20 16:08:32 2014] [error] [client 112.134.180.165]     class Permission(models.Model):
[Mon Oct 20 16:08:32 2014] [error] [client 112.134.180.165]   File "/usr/local/lib/python2.7/dist-packages/django/db/models/base.py", line 125, in __new__
[Mon Oct 20 16:08:32 2014] [error] [client 112.134.180.165]     new_class.add_to_class('_meta', Options(meta, **kwargs))
[Mon Oct 20 16:08:32 2014] [error] [client 112.134.180.165]   File "/usr/local/lib/python2.7/dist-packages/django/db/models/base.py", line 300, in add_to_class
[Mon Oct 20 16:08:32 2014] [error] [client 112.134.180.165]     value.contribute_to_class(cls, name)
[Mon Oct 20 16:08:32 2014] [error] [client 112.134.180.165]   File "/usr/local/lib/python2.7/dist-packages/django/db/models/options.py", line 166, in contribute_to_class
[Mon Oct 20 16:08:32 2014] [error] [client 112.134.180.165]     self.db_table = truncate_name(self.db_table, connection.ops.max_name_length())
[Mon Oct 20 16:08:32 2014] [error] [client 112.134.180.165]   File "/usr/local/lib/python2.7/dist-packages/django/db/__init__.py", line 40, in __getattr__
[Mon Oct 20 16:08:32 2014] [error] [client 112.134.180.165]     return getattr(connections[DEFAULT_DB_ALIAS], item)
[Mon Oct 20 16:08:32 2014] [error] [client 112.134.180.165]   File "/usr/local/lib/python2.7/dist-packages/django/db/utils.py", line 242, in __getitem__
[Mon Oct 20 16:08:32 2014] [error] [client 112.134.180.165]     backend = load_backend(db['ENGINE'])
[Mon Oct 20 16:08:32 2014] [error] [client 112.134.180.165]   File "/usr/local/lib/python2.7/dist-packages/django/db/utils.py", line 108, in load_backend
[Mon Oct 20 16:08:32 2014] [error] [client 112.134.180.165]     return import_module('%s.base' % backend_name)
[Mon Oct 20 16:08:32 2014] [error] [client 112.134.180.165]   File "/usr/lib/python2.7/importlib/__init__.py", line 37, in import_module
[Mon Oct 20 16:08:32 2014] [error] [client 112.134.180.165]     __import__(name)
[Mon Oct 20 16:08:32 2014] [error] [client 112.134.180.165]   File "/usr/local/lib/python2.7/dist-packages/django/db/backends/mysql/base.py", line 17, in <module>
[Mon Oct 20 16:08:32 2014] [error] [client 112.134.180.165]     raise ImproperlyConfigured("Error loading MySQLdb module: %s" % e)
[Mon Oct 20 16:08:32 2014] [error] [client 112.134.180.165] ImproperlyConfigured: Error loading MySQLdb module: No module named MySQLdb
[Mon Oct 20 16:13:05 2014] [notice] caught SIGTERM, shutting down
[Mon Oct 20 16:13:06 2014] [notice] Apache/2.2.22 (Debian) mod_wsgi/3.3 Python/2.7.3 configured -- resuming normal operations
[Mon Oct 20 16:15:27 2014] [notice] caught SIGTERM, shutting down
[Mon Oct 20 16:15:28 2014] [notice] Apache/2.2.22 (Debian) mod_wsgi/3.3 Python/2.7.3 configured -- resuming normal operations
[Mon Oct 20 16:18:08 2014] [notice] caught SIGTERM, shutting down
[Mon Oct 20 16:18:08 2014] [notice] Apache/2.2.22 (Debian) mod_wsgi/3.3 Python/2.7.3 configured -- resuming normal operations
[Mon Oct 20 16:45:13 2014] [notice] caught SIGTERM, shutting down
[Mon Oct 20 16:45:13 2014] [notice] Apache/2.2.22 (Debian) mod_wsgi/3.3 Python/2.7.3 configured -- resuming normal operations
[Mon Oct 20 16:45:22 2014] [error] [client 112.134.180.165] File does not exist: /var/www/care
[Mon Oct 20 16:45:23 2014] [error] [client 112.134.180.165] File does not exist: /var/www/care
[Mon Oct 20 16:46:13 2014] [error] [client 112.134.180.165] File does not exist: /var/www/care
[Mon Oct 20 16:46:25 2014] [error] [client 112.134.180.165] File does not exist: /var/www/care
[Mon Oct 20 16:46:26 2014] [error] [client 112.134.180.165] File does not exist: /var/www/care
[Mon Oct 20 16:46:27 2014] [error] [client 112.134.180.165] File does not exist: /var/www/care
[Mon Oct 20 16:46:27 2014] [error] [client 112.134.180.165] File does not exist: /var/www/care
[Mon Oct 20 16:46:28 2014] [error] [client 112.134.180.165] File does not exist: /var/www/care
[Mon Oct 20 16:46:28 2014] [error] [client 112.134.180.165] File does not exist: /var/www/care
[Mon Oct 20 16:46:28 2014] [error] [client 112.134.180.165] File does not exist: /var/www/care
[Mon Oct 20 16:46:29 2014] [error] [client 112.134.180.165] File does not exist: /var/www/care
[Mon Oct 20 16:46:29 2014] [error] [client 112.134.180.165] File does not exist: /var/www/care
[Mon Oct 20 16:46:29 2014] [error] [client 112.134.180.165] File does not exist: /var/www/care
[Mon Oct 20 16:46:43 2014] [error] [client 112.134.180.165] File does not exist: /var/www/care
[Mon Oct 20 16:46:44 2014] [error] [client 112.134.180.165] File does not exist: /var/www/care
[Mon Oct 20 16:46:45 2014] [error] [client 112.134.180.165] File does not exist: /var/www/care
[Mon Oct 20 16:46:47 2014] [error] [client 112.134.180.165] File does not exist: /var/www/care
[Mon Oct 20 17:16:58 2014] [notice] SIGUSR1 received.  Doing graceful restart
[Mon Oct 20 17:16:58 2014] [notice] Apache/2.2.22 (Debian) mod_wsgi/3.3 Python/2.7.3 configured -- resuming normal operations
[Mon Oct 20 17:20:33 2014] [error] /usr/local/lib/python2.7/dist-packages/django/db/models/fields/__init__.py:1278: RuntimeWarning: DateTimeField Picture.date_pub received a naive datetime (2014-10-20 00:00:00) while time zone support is active.
[Mon Oct 20 17:20:33 2014] [error]   RuntimeWarning)
[Mon Oct 20 17:20:33 2014] [error] 
[Mon Oct 20 17:20:33 2014] [error] /usr/local/lib/python2.7/dist-packages/django/db/models/fields/__init__.py:1278: RuntimeWarning: DateTimeField Picture.date_pub received a naive datetime (2014-10-20 23:59:59.999999) while time zone support is active.
[Mon Oct 20 17:20:33 2014] [error]   RuntimeWarning)
[Mon Oct 20 17:20:33 2014] [error] 
[Mon Oct 20 17:21:06 2014] [error] /usr/local/lib/python2.7/dist-packages/django/db/models/fields/__init__.py:1278: RuntimeWarning: DateTimeField Category.date_pub received a naive datetime (2014-10-20 00:00:00) while time zone support is active.
[Mon Oct 20 17:21:06 2014] [error]   RuntimeWarning)
[Mon Oct 20 17:21:06 2014] [error] 
[Mon Oct 20 17:21:06 2014] [error] /usr/local/lib/python2.7/dist-packages/django/db/models/fields/__init__.py:1278: RuntimeWarning: DateTimeField Category.date_pub received a naive datetime (2014-10-20 23:59:59.999999) while time zone support is active.
[Mon Oct 20 17:21:06 2014] [error]   RuntimeWarning)
[Mon Oct 20 17:21:06 2014] [error] 
[Mon Oct 20 17:21:31 2014] [error] /usr/local/lib/python2.7/dist-packages/django/db/models/fields/__init__.py:1278: RuntimeWarning: DateTimeField Picture.date_pub received a naive datetime (2014-10-20 00:00:00) while time zone support is active.
[Mon Oct 20 17:21:31 2014] [error]   RuntimeWarning)
[Mon Oct 20 17:21:31 2014] [error] 
[Mon Oct 20 17:21:31 2014] [error] /usr/local/lib/python2.7/dist-packages/django/db/models/fields/__init__.py:1278: RuntimeWarning: DateTimeField Picture.date_pub received a naive datetime (2014-10-20 23:59:59.999999) while time zone support is active.
[Mon Oct 20 17:21:31 2014] [error]   RuntimeWarning)
[Mon Oct 20 17:21:31 2014] [error] 
[Mon Oct 20 17:24:12 2014] [notice] caught SIGTERM, shutting down
[Mon Oct 20 17:24:13 2014] [notice] Apache/2.2.22 (Debian) mod_wsgi/3.3 Python/2.7.3 configured -- resuming normal operations
[Mon Oct 20 17:24:27 2014] [error] /usr/local/lib/python2.7/dist-packages/django/db/models/fields/__init__.py:1278: RuntimeWarning: DateTimeField Picture.date_pub received a naive datetime (2014-10-20 00:00:00) while time zone support is active.
[Mon Oct 20 17:24:27 2014] [error]   RuntimeWarning)
[Mon Oct 20 17:24:27 2014] [error] 
[Mon Oct 20 17:24:27 2014] [error] /usr/local/lib/python2.7/dist-packages/django/db/models/fields/__init__.py:1278: RuntimeWarning: DateTimeField Picture.date_pub received a naive datetime (2014-10-20 23:59:59.999999) while time zone support is active.
[Mon Oct 20 17:24:27 2014] [error]   RuntimeWarning)
[Mon Oct 20 17:24:27 2014] [error] 
[Mon Oct 20 17:39:06 2014] [notice] caught SIGTERM, shutting down
[Mon Oct 20 17:39:06 2014] [notice] Apache/2.2.22 (Debian) mod_wsgi/3.3 Python/2.7.3 configured -- resuming normal operations
[Mon Oct 20 17:39:17 2014] [error] /usr/local/lib/python2.7/dist-packages/django/db/models/fields/__init__.py:1278: RuntimeWarning: DateTimeField Picture.date_pub received a naive datetime (2014-10-20 00:00:00) while time zone support is active.
[Mon Oct 20 17:39:17 2014] [error]   RuntimeWarning)
[Mon Oct 20 17:39:17 2014] [error] 
[Mon Oct 20 17:39:17 2014] [error] /usr/local/lib/python2.7/dist-packages/django/db/models/fields/__init__.py:1278: RuntimeWarning: DateTimeField Picture.date_pub received a naive datetime (2014-10-20 23:59:59.999999) while time zone support is active.
[Mon Oct 20 17:39:17 2014] [error]   RuntimeWarning)
[Mon Oct 20 17:39:17 2014] [error] 
[Mon Oct 20 17:46:44 2014] [error] /usr/local/lib/python2.7/dist-packages/django/db/models/fields/__init__.py:1278: RuntimeWarning: DateTimeField Category.date_pub received a naive datetime (2014-10-20 00:00:00) while time zone support is active.
[Mon Oct 20 17:46:44 2014] [error]   RuntimeWarning)
[Mon Oct 20 17:46:44 2014] [error] 
[Mon Oct 20 17:46:44 2014] [error] /usr/local/lib/python2.7/dist-packages/django/db/models/fields/__init__.py:1278: RuntimeWarning: DateTimeField Category.date_pub received a naive datetime (2014-10-20 23:59:59.999999) while time zone support is active.
[Mon Oct 20 17:46:44 2014] [error]   RuntimeWarning)
[Mon Oct 20 17:46:44 2014] [error] 
[Mon Oct 20 17:49:30 2014] [error] /usr/local/lib/python2.7/dist-packages/django/db/models/fields/__init__.py:1278: RuntimeWarning: DateTimeField Category.date_pub received a naive datetime (2014-10-20 00:00:00) while time zone support is active.
[Mon Oct 20 17:49:30 2014] [error]   RuntimeWarning)
[Mon Oct 20 17:49:30 2014] [error] 
[Mon Oct 20 17:49:30 2014] [error] /usr/local/lib/python2.7/dist-packages/django/db/models/fields/__init__.py:1278: RuntimeWarning: DateTimeField Category.date_pub received a naive datetime (2014-10-20 23:59:59.999999) while time zone support is active.
[Mon Oct 20 17:49:30 2014] [error]   RuntimeWarning)
[Mon Oct 20 17:49:30 2014] [error] 
[Mon Oct 20 17:53:08 2014] [error] /usr/local/lib/python2.7/dist-packages/django/db/models/fields/__init__.py:1278: RuntimeWarning: DateTimeField Picture.date_pub received a naive datetime (2014-10-20 00:00:00) while time zone support is active.
[Mon Oct 20 17:53:08 2014] [error]   RuntimeWarning)
[Mon Oct 20 17:53:08 2014] [error] 
[Mon Oct 20 17:53:08 2014] [error] /usr/local/lib/python2.7/dist-packages/django/db/models/fields/__init__.py:1278: RuntimeWarning: DateTimeField Picture.date_pub received a naive datetime (2014-10-20 23:59:59.999999) while time zone support is active.
[Mon Oct 20 17:53:08 2014] [error]   RuntimeWarning)
[Mon Oct 20 17:53:08 2014] [error] 
[Mon Oct 20 17:54:00 2014] [error] /usr/local/lib/python2.7/dist-packages/django/db/models/fields/__init__.py:1278: RuntimeWarning: DateTimeField Tag.date_pub received a naive datetime (2014-10-20 00:00:00) while time zone support is active.
[Mon Oct 20 17:54:00 2014] [error]   RuntimeWarning)
[Mon Oct 20 17:54:00 2014] [error] 
[Mon Oct 20 17:54:00 2014] [error] /usr/local/lib/python2.7/dist-packages/django/db/models/fields/__init__.py:1278: RuntimeWarning: DateTimeField Tag.date_pub received a naive datetime (2014-10-20 23:59:59.999999) while time zone support is active.
[Mon Oct 20 17:54:00 2014] [error]   RuntimeWarning)
[Mon Oct 20 17:54:00 2014] [error] 
[Mon Oct 20 17:54:06 2014] [error] /usr/local/lib/python2.7/dist-packages/django/db/models/fields/__init__.py:1278: RuntimeWarning: DateTimeField Tag.date_pub received a naive datetime (2014-10-20 00:00:00) while time zone support is active.
[Mon Oct 20 17:54:06 2014] [error]   RuntimeWarning)
[Mon Oct 20 17:54:06 2014] [error] 
[Mon Oct 20 17:54:06 2014] [error] /usr/local/lib/python2.7/dist-packages/django/db/models/fields/__init__.py:1278: RuntimeWarning: DateTimeField Tag.date_pub received a naive datetime (2014-10-20 23:59:59.999999) while time zone support is active.
[Mon Oct 20 17:54:06 2014] [error]   RuntimeWarning)
[Mon Oct 20 17:54:06 2014] [error] 
[Mon Oct 20 18:26:52 2014] [error] [client 31.202.17.34] File does not exist: /var/www/apple-touch-icon.png
[Mon Oct 20 18:26:52 2014] [error] [client 31.202.17.34] File does not exist: /var/www/favicon.ico
[Mon Oct 20 18:26:52 2014] [error] [client 66.249.81.105] File does not exist: /var/www/favicon.ico
[Mon Oct 20 18:37:42 2014] [notice] caught SIGTERM, shutting down
[Mon Oct 20 18:37:43 2014] [notice] Apache/2.2.22 (Debian) mod_wsgi/3.3 Python/2.7.3 configured -- resuming normal operations
[Mon Oct 20 18:38:11 2014] [error] /usr/local/lib/python2.7/dist-packages/django/db/models/fields/__init__.py:1278: RuntimeWarning: DateTimeField Category.date_pub received a naive datetime (2014-10-20 00:00:00) while time zone support is active.
[Mon Oct 20 18:38:11 2014] [error]   RuntimeWarning)
[Mon Oct 20 18:38:11 2014] [error] 
[Mon Oct 20 18:38:11 2014] [error] /usr/local/lib/python2.7/dist-packages/django/db/models/fields/__init__.py:1278: RuntimeWarning: DateTimeField Category.date_pub received a naive datetime (2014-10-20 23:59:59.999999) while time zone support is active.
[Mon Oct 20 18:38:11 2014] [error]   RuntimeWarning)
[Mon Oct 20 18:38:11 2014] [error] 
[Mon Oct 20 18:38:28 2014] [error] /usr/local/lib/python2.7/dist-packages/django/db/models/fields/__init__.py:1278: RuntimeWarning: DateTimeField Picture.date_pub received a naive datetime (2014-10-20 00:00:00) while time zone support is active.
[Mon Oct 20 18:38:28 2014] [error]   RuntimeWarning)
[Mon Oct 20 18:38:28 2014] [error] 
[Mon Oct 20 18:38:28 2014] [error] /usr/local/lib/python2.7/dist-packages/django/db/models/fields/__init__.py:1278: RuntimeWarning: DateTimeField Picture.date_pub received a naive datetime (2014-10-20 23:59:59.999999) while time zone support is active.
[Mon Oct 20 18:38:28 2014] [error]   RuntimeWarning)
[Mon Oct 20 18:38:28 2014] [error] 
[Mon Oct 20 18:39:21 2014] [error] /usr/local/lib/python2.7/dist-packages/django/db/models/fields/__init__.py:1278: RuntimeWarning: DateTimeField Picture.date_pub received a naive datetime (2014-10-20 00:00:00) while time zone support is active.
[Mon Oct 20 18:39:21 2014] [error]   RuntimeWarning)
[Mon Oct 20 18:39:21 2014] [error] 
[Mon Oct 20 18:39:21 2014] [error] /usr/local/lib/python2.7/dist-packages/django/db/models/fields/__init__.py:1278: RuntimeWarning: DateTimeField Picture.date_pub received a naive datetime (2014-10-20 23:59:59.999999) while time zone support is active.
[Mon Oct 20 18:39:21 2014] [error]   RuntimeWarning)
[Mon Oct 20 18:39:21 2014] [error] 
[Mon Oct 20 18:44:35 2014] [notice] caught SIGTERM, shutting down
[Mon Oct 20 18:44:36 2014] [notice] Apache/2.2.22 (Debian) mod_wsgi/3.3 Python/2.7.3 configured -- resuming normal operations
[Mon Oct 20 18:46:00 2014] [notice] caught SIGTERM, shutting down
[Mon Oct 20 18:46:01 2014] [notice] Apache/2.2.22 (Debian) mod_wsgi/3.3 Python/2.7.3 configured -- resuming normal operations
[Mon Oct 20 18:47:22 2014] [notice] caught SIGTERM, shutting down
[Mon Oct 20 18:47:23 2014] [notice] Apache/2.2.22 (Debian) mod_wsgi/3.3 Python/2.7.3 configured -- resuming normal operations
[Mon Oct 20 18:50:52 2014] [notice] caught SIGTERM, shutting down
[Mon Oct 20 18:50:53 2014] [notice] Apache/2.2.22 (Debian) mod_wsgi/3.3 Python/2.7.3 configured -- resuming normal operations
[Tue Oct 21 06:19:06 2014] [error] [client 187.214.0.111] File does not exist: /var/www/khkh
[Tue Oct 21 06:19:06 2014] [error] [client 187.214.0.111] File does not exist: /var/www/phpMyAdmin
[Tue Oct 21 06:19:07 2014] [error] [client 187.214.0.111] File does not exist: /var/www/pma
[Tue Oct 21 06:19:07 2014] [error] [client 187.214.0.111] File does not exist: /var/www/myadmin
[Tue Oct 21 07:13:54 2014] [notice] caught SIGTERM, shutting down
[Tue Oct 21 07:13:55 2014] [notice] Apache/2.2.22 (Debian) mod_wsgi/3.3 Python/2.7.3 configured -- resuming normal operations
[Tue Oct 21 08:41:08 2014] [error] [client 174.139.241.90] File does not exist: /var/www/web-console
[Tue Oct 21 09:42:23 2014] [notice] caught SIGTERM, shutting down
[Tue Oct 21 09:42:24 2014] [notice] Apache/2.2.22 (Debian) mod_wsgi/3.3 Python/2.7.3 configured -- resuming normal operations
[Wed Oct 22 14:22:53 2014] [error] [client 93.156.182.56] client sent HTTP/1.1 request without hostname (see RFC2616 section 14.23): /tmUnblock.cgi
[Wed Oct 22 15:06:24 2014] [error] [client 5.61.39.9] client sent HTTP/1.1 request without hostname (see RFC2616 section 14.23): /w00tw00t.at.ISC.SANS.DFind:)
[Wed Oct 22 16:16:49 2014] [error] [client 76.79.130.74] client sent HTTP/1.1 request without hostname (see RFC2616 section 14.23): /tmUnblock.cgi
[Thu Oct 23 05:47:10 2014] [error] [client 198.20.69.74] File does not exist: /var/www/robots.txt
[Thu Oct 23 11:12:36 2014] [error] [client 208.43.140.35] script not found or unable to stat: /usr/lib/cgi-bin/test-cgi, referer: () { foo;};echo; /usr/bin/id
[Thu Oct 23 11:12:36 2014] [error] [client 208.43.140.35] script not found or unable to stat: /usr/lib/cgi-bin/test.cgi, referer: () { foo;};echo; /usr/bin/id
[Thu Oct 23 11:12:37 2014] [error] [client 208.43.140.35] script not found or unable to stat: /usr/lib/cgi-bin/test.pl, referer: () { foo;};echo; /usr/bin/id
[Thu Oct 23 11:12:37 2014] [error] [client 208.43.140.35] script not found or unable to stat: /usr/lib/cgi-bin/test.sh, referer: () { foo;};echo; /usr/bin/id
[Thu Oct 23 16:38:45 2014] [error] [client 207.194.245.66] client sent HTTP/1.1 request without hostname (see RFC2616 section 14.23): /tmUnblock.cgi
[Thu Oct 23 17:35:15 2014] [error] [client 37.57.27.228] File does not exist: /var/www/favicon.ico
[Thu Oct 23 17:35:24 2014] [error] [client 37.57.27.228] File does not exist: /var/www/care
[Fri Oct 24 06:39:28 2014] [error] [client 69.174.245.163] File does not exist: /var/www/w00tw00t.at.blackhats.romanian.anti-sec:)
[Fri Oct 24 06:39:28 2014] [error] [client 69.174.245.163] File does not exist: /var/www/phpMyAdmin
[Fri Oct 24 06:39:29 2014] [error] [client 69.174.245.163] File does not exist: /var/www/phpmyadmin
[Fri Oct 24 06:39:29 2014] [error] [client 69.174.245.163] File does not exist: /var/www/pma
[Fri Oct 24 06:39:29 2014] [error] [client 69.174.245.163] File does not exist: /var/www/myadmin
[Fri Oct 24 06:39:29 2014] [error] [client 69.174.245.163] File does not exist: /var/www/MyAdmin
[Fri Oct 24 08:12:33 2014] [error] [client 66.249.93.96] File does not exist: /var/www/favicon.ico
[Fri Oct 24 10:41:26 2014] [error] [client 84.24.186.32] client sent HTTP/1.1 request without hostname (see RFC2616 section 14.23): /tmUnblock.cgi
[Fri Oct 24 11:55:19 2014] [error] [client 12.167.210.14] Invalid method in request \x80w\x01\x03\x01
[Fri Oct 24 11:55:20 2014] [error] [client 12.167.210.14] File does not exist: /var/www/HNAP1, referer: http://178.62.63.179/
[Fri Oct 24 20:36:52 2014] [error] [client 99.58.230.86] client sent HTTP/1.1 request without hostname (see RFC2616 section 14.23): /tmUnblock.cgi
[Sat Oct 25 04:44:25 2014] [error] [client 146.185.251.100] File does not exist: /var/www/rom-0
[Sat Oct 25 08:01:38 2014] [error] [client 71.6.165.200] File does not exist: /var/www/robots.txt
[Sat Oct 25 08:19:34 2014] [error] [client 117.27.254.25] File does not exist: /var/www/index.action
[Sat Oct 25 08:19:34 2014] [error] [client 117.27.254.25] File does not exist: /var/www/index.do
[Sat Oct 25 08:19:35 2014] [error] [client 117.27.254.25] File does not exist: /var/www/login.action
[Sat Oct 25 08:19:36 2014] [error] [client 117.27.254.25] File does not exist: /var/www/login.do
[Sat Oct 25 10:14:37 2014] [error] [client 184.154.49.170] Invalid URI in request GET <title>phpMyAdmin HTTP/1.1
[Sat Oct 25 10:14:37 2014] [error] [client 184.154.49.170] File does not exist: /var/www/phpmyadmin
[Sat Oct 25 10:14:37 2014] [error] [client 184.154.49.170] File does not exist: /var/www/phpMyAdmin
[Sat Oct 25 10:14:37 2014] [error] [client 184.154.49.170] File does not exist: /var/www/PMA
[Sat Oct 25 10:14:38 2014] [error] [client 184.154.49.170] File does not exist: /var/www/pma
[Sat Oct 25 10:14:38 2014] [error] [client 184.154.49.170] File does not exist: /var/www/admin
[Sat Oct 25 10:14:38 2014] [error] [client 184.154.49.170] File does not exist: /var/www/dbadmin
[Sat Oct 25 10:14:38 2014] [error] [client 184.154.49.170] File does not exist: /var/www/sql
[Sat Oct 25 10:14:38 2014] [error] [client 184.154.49.170] File does not exist: /var/www/mysql
[Sat Oct 25 10:14:39 2014] [error] [client 184.154.49.170] File does not exist: /var/www/myadmin
[Sat Oct 25 10:14:39 2014] [error] [client 184.154.49.170] File does not exist: /var/www/phpmyadmin2
[Sat Oct 25 10:14:39 2014] [error] [client 184.154.49.170] File does not exist: /var/www/phpMyAdmin2
[Sat Oct 25 10:14:39 2014] [error] [client 184.154.49.170] File does not exist: /var/www/phpMyAdmin-2
[Sat Oct 25 10:14:39 2014] [error] [client 184.154.49.170] File does not exist: /var/www/php-my-admin
[Sat Oct 25 10:14:40 2014] [error] [client 184.154.49.170] File does not exist: /var/www/sqlmanager
[Sat Oct 25 10:14:40 2014] [error] [client 184.154.49.170] File does not exist: /var/www/mysqlmanager
[Sat Oct 25 10:14:40 2014] [error] [client 184.154.49.170] File does not exist: /var/www/p
[Sat Oct 25 10:14:40 2014] [error] [client 184.154.49.170] File does not exist: /var/www/php-myadmin
[Sat Oct 25 10:14:40 2014] [error] [client 184.154.49.170] File does not exist: /var/www/phpmy-admin
[Sat Oct 25 10:14:41 2014] [error] [client 184.154.49.170] File does not exist: /var/www/webadmin
[Sat Oct 25 10:14:41 2014] [error] [client 184.154.49.170] File does not exist: /var/www/sqlweb
[Sat Oct 25 10:14:41 2014] [error] [client 184.154.49.170] File does not exist: /var/www/websql
[Sat Oct 25 10:14:41 2014] [error] [client 184.154.49.170] File does not exist: /var/www/webdb
[Sat Oct 25 10:14:41 2014] [error] [client 184.154.49.170] File does not exist: /var/www/mysqladmin
[Sat Oct 25 10:14:42 2014] [error] [client 184.154.49.170] File does not exist: /var/www/mysql-admin
[Sat Oct 25 10:14:42 2014] [error] [client 184.154.49.170] File does not exist: /var/www/scripts
[Sat Oct 25 10:14:42 2014] [error] [client 184.154.49.170] File does not exist: /var/www/admin
[Sat Oct 25 10:14:42 2014] [error] [client 184.154.49.170] File does not exist: /var/www/admin
[Sat Oct 25 10:14:42 2014] [error] [client 184.154.49.170] File does not exist: /var/www/admin
[Sat Oct 25 10:14:42 2014] [error] [client 184.154.49.170] File does not exist: /var/www/db
[Sat Oct 25 10:14:43 2014] [error] [client 184.154.49.170] File does not exist: /var/www/dbadmin
[Sat Oct 25 10:14:43 2014] [error] [client 184.154.49.170] File does not exist: /var/www/myadmin
[Sat Oct 25 10:14:43 2014] [error] [client 184.154.49.170] File does not exist: /var/www/mysql
[Sat Oct 25 10:14:43 2014] [error] [client 184.154.49.170] File does not exist: /var/www/mysqladmin
[Sat Oct 25 10:14:43 2014] [error] [client 184.154.49.170] File does not exist: /var/www/typo3
[Sat Oct 25 10:14:44 2014] [error] [client 184.154.49.170] File does not exist: /var/www/phpadmin
[Sat Oct 25 10:14:44 2014] [error] [client 184.154.49.170] File does not exist: /var/www/phpMyAdmin
[Sat Oct 25 10:14:44 2014] [error] [client 184.154.49.170] File does not exist: /var/www/phpmyadmin
[Sat Oct 25 10:14:44 2014] [error] [client 184.154.49.170] File does not exist: /var/www/phpmyadmin1
[Sat Oct 25 10:14:44 2014] [error] [client 184.154.49.170] File does not exist: /var/www/phpmyadmin2
[Sat Oct 25 10:14:45 2014] [error] [client 184.154.49.170] File does not exist: /var/www/pma
[Sat Oct 25 10:14:45 2014] [error] [client 184.154.49.170] File does not exist: /var/www/web
[Sat Oct 25 10:14:45 2014] [error] [client 184.154.49.170] File does not exist: /var/www/xampp
[Sat Oct 25 10:14:45 2014] [error] [client 184.154.49.170] File does not exist: /var/www/web
[Sat Oct 25 10:14:45 2014] [error] [client 184.154.49.170] File does not exist: /var/www/php-my-admin
[Sat Oct 25 10:14:45 2014] [error] [client 184.154.49.170] File does not exist: /var/www/websql
[Sat Oct 25 10:14:46 2014] [error] [client 184.154.49.170] File does not exist: /var/www/phpmyadmin
[Sat Oct 25 10:14:46 2014] [error] [client 184.154.49.170] File does not exist: /var/www/phpMyAdmin
[Sat Oct 25 10:14:46 2014] [error] [client 184.154.49.170] File does not exist: /var/www/phpMyAdmin-2
[Sat Oct 25 10:14:46 2014] [error] [client 184.154.49.170] File does not exist: /var/www/php-my-admin
[Sat Oct 25 10:14:46 2014] [error] [client 184.154.49.170] File does not exist: /var/www/sqlmanager
[Sat Oct 25 10:14:47 2014] [error] [client 184.154.49.170] File does not exist: /var/www/mysqlmanager
[Sat Oct 25 10:14:47 2014] [error] [client 184.154.49.170] File does not exist: /var/www/p
[Sat Oct 25 10:14:47 2014] [error] [client 184.154.49.170] File does not exist: /var/www/PMA2005
[Sat Oct 25 10:14:47 2014] [error] [client 184.154.49.170] File does not exist: /var/www/pma2005
[Sat Oct 25 10:14:47 2014] [error] [client 184.154.49.170] File does not exist: /var/www/phpmanager
[Sat Oct 25 10:14:48 2014] [error] [client 184.154.49.170] File does not exist: /var/www/php-myadmin
[Sat Oct 25 10:14:48 2014] [error] [client 184.154.49.170] File does not exist: /var/www/phpmy-admin
[Sat Oct 25 10:14:48 2014] [error] [client 184.154.49.170] File does not exist: /var/www/webadmin
[Sat Oct 25 10:14:48 2014] [error] [client 184.154.49.170] File does not exist: /var/www/sqlweb
[Sat Oct 25 10:14:48 2014] [error] [client 184.154.49.170] File does not exist: /var/www/websql
[Sat Oct 25 10:14:49 2014] [error] [client 184.154.49.170] File does not exist: /var/www/webdb
[Sat Oct 25 10:14:49 2014] [error] [client 184.154.49.170] File does not exist: /var/www/mysqladmin
[Sat Oct 25 10:14:49 2014] [error] [client 184.154.49.170] File does not exist: /var/www/mysql-admin
[Sat Oct 25 10:14:49 2014] [error] [client 184.154.49.170] Invalid URI in request GET  HTTP/1.1
[Sat Oct 25 17:45:35 2014] [notice] caught SIGTERM, shutting down
[Sat Oct 25 17:45:36 2014] [notice] Apache/2.2.22 (Debian) mod_wsgi/3.3 Python/2.7.3 configured -- resuming normal operations
[Sat Oct 25 18:13:36 2014] [notice] caught SIGTERM, shutting down
[Sat Oct 25 18:13:37 2014] [notice] Apache/2.2.22 (Debian) mod_wsgi/3.3 Python/2.7.3 configured -- resuming normal operations
[Sat Oct 25 18:14:35 2014] [notice] caught SIGTERM, shutting down
[Sat Oct 25 18:14:36 2014] [notice] Apache/2.2.22 (Debian) mod_wsgi/3.3 Python/2.7.3 configured -- resuming normal operations
[Sat Oct 25 18:15:06 2014] [notice] caught SIGTERM, shutting down
[Sat Oct 25 18:15:07 2014] [notice] Apache/2.2.22 (Debian) mod_wsgi/3.3 Python/2.7.3 configured -- resuming normal operations
[Sat Oct 25 18:57:39 2014] [notice] caught SIGTERM, shutting down
[Sat Oct 25 18:57:40 2014] [notice] Apache/2.2.22 (Debian) mod_wsgi/3.3 Python/2.7.3 configured -- resuming normal operations
[Sat Oct 25 18:58:41 2014] [notice] caught SIGTERM, shutting down
[Sat Oct 25 18:58:42 2014] [notice] Apache/2.2.22 (Debian) mod_wsgi/3.3 Python/2.7.3 configured -- resuming normal operations
[Sat Oct 25 19:09:12 2014] [notice] caught SIGTERM, shutting down
[Sat Oct 25 19:09:13 2014] [notice] Apache/2.2.22 (Debian) mod_wsgi/3.3 Python/2.7.3 configured -- resuming normal operations
